Workbook

Sheet Data_Survey_Jan2026

Sheet Data_survey
A1: Sl | B1: Location | C1: Company Name | D1: Small/Medium/Large | E1: Key Dimension(KD):About Enterprises, Owners Motivation | H1: KD: Buy process,Demand Planning & Procurement | L1: KD:Current Operational Process , Legacy & new machine to balance | N1: Key Enablers(KE): Effortable Digital technologies | Q1: KD:Owner's viewpoints, | V1: Key Outcome(KO)- Growth and Effeciency.Challenges to penetrate the global market. | AD1: Key Enabler :Certification &Standarization | AG1: KD: Financial challenges ,lack of transparency in institutional support , and knowledge gap on Ecosystem Integration | AM1: KD: Administrative , Operational challenges & Eco system Integration challenges | AP1: Enabler: Engaging local hire | AS1: Key Dimension: Skill Gap ,Retaining resources and workforce Management | AW1: CSR
B2: Jamshedpur | E2: Year of Establishment | F2: Main Product | G2: Owner Qualification/Skill/Education | H2: Do you use advance Digital tool for planning, demand forecasting and supply chain? 1.Very Frequently 2. Frequently 3. Occasionally 4.Rarely 5.Never | I2: Do you face Price challenges during procurement? 1.Very Frequently 2.Frequently 3.Occasionally 4.Rarely 5.Never | J2: Do you face supply chain challenges inlcuding ad-hoc demand ? 1. Very Frequently 2. Frequently 3.Occasionally 4.Rarely 5.Never | K2: Do you think increasing demand volume is one of the key challenges for your growth? 1.Strongly Agree 2.Agree 3.Undecided 4. Disagree 5. Strongly Disagree | L2: Do you use existing traditional machines? 1. Always 2. Very Frequently 3. Occasionally 4. Rarely 5.Never | M2: What type of the Process you following during manufacturing? 1. Fully -Automated 2. semi-automated 3. Manual | N2: Do you use digital tools to collaborate with suppliers ? 1. Very Frequently 2. Frequently 3.Occasionally 4.Rarely 5.Never | O2: Do you use digital project management tool during operational and execution processes? 1. Very Frequently 2. Frequently 3. Occasionally 4. Rarely 5. Never | P2: Do you use of Digital technologies during manufacturing process? 1.Always 2.Often 3.Sometimes 4.Rarely 5. Never | Q2: Do you think replacing old machine would improve business growth? 1.Strongly Agree 2.Agree 3.Undecided 4. Disagree 5. Strongly Disagree | R2: Owners viewpoint on Automation & Digitalization: Do you think digital Automation will be beneficial with respect to increase demand and business growth? 1.Strongly Agree 2.Agree 3.Undecided 4. Disagree 5. Strongly Disagree | S2: Do you think digital & AI technologies help on buyers & seller connect? 1.Strongly Agree 2.Agree 3.Undecided 4. Disagree 5. Strongly Disagree | T2: Do you think digital & AI technologies help to reduce waste & track parts during manufacturing? 1.Strongly Agree 2.Agree 3.Undecided 4. Disagree 5. Strongly Disagree | U2: Do you think AI technologies, Email, Whats app video calls, and messaging apps help in quick decision-making and reducing paperwork? 1.Strongly Agree 2.Agree 3.Undecided 4. Disagree 5. Strongly Disagree | V2: Major Market and Customer dependency? 1. Dependency on very few Local and regional customers 2. Multiple local and Regional customer 3. Domestic - larger customer(s) within India 4. Export to other countries | W2: Do you export to other Countries/Regions? 1. Yes 2. No | X2: Main domestic market base : 1. B2B customer in Semi-urban India 2. Alliance with private and Govt aggregator 3. Multiple Big larger manufacture(s) and assemblers 4. Supplying to other small companies(makes ANCILLARIES) 5. Supplying to Single large manufacturer and assembler. | Y2: Aprox Turn over(Cr) ( This colum is just for reference) | Z2: Aprox Turn over(Cr) 1. Between 5 -10 cr 2. Between 10-15 cr 3. Between 15-20 4. Between 20-25 5. >25 Cr | AA2: Do you agree digital & AI technologies helps to connect new prospecting customer /market? 1.Strongly Agree 2.Agree 3.Undecided 4. Disagree 5. Strongly Disagree | AB2: Do you agree that digital technologies facilitate quick decision-making and bring efficiency in operational process? 1.Strongly Agree 2.Agree 3.Undecided 4. Disagree 5. Strongly Disagree | AC2: Do you agree that digital technologies help to improve product quality, the inspection process and reduce product defect? 1.Strongly Agree 2.Agree 3.Undecided 4. Disagree 5. Strongly Disagree | AD2: Do you follow any product Certification process? 1.Always 2.Often 3.Sometimes 4.Rarely 5. Never | AE2: Do you think product standardization is one of the key challenges to scaling up your business? 1.Strongly Agree 2.Agree 3.Undecided 4. Disagree 5. Strongly Disagree | AF2: Do you think product certification, checking quality, and testing are key challenges to your business growth ? 1.Strongly Agree 2.Agree 3.Undecided 4. Disagree 5. Strongly Disagree | AG2: How frequently do you receive required funding on time from the Bank and financial institute? 1. Very Frequently 2. Frequently 3. Occasionally 4. Rarely 5. Never | AH2: Do you think slowdown in major industries (Large Industries) has adversely affected ancillary as Small industries are dependent on large Industries? 1.Strongly Agree 2.Agree 3.Undecided 4. Disagree 5. Strongly Disagree | AI2: Do you think following up with multiple offices is a difficult and lengthy process? Lack of transparency on financial help and lack of knowledge about small companies results financial institutions taking longer to provide loan? 1. Strongly Agree 2. Agree 3. Undecided 4. Disagree 5. Strongly Disagree | AJ2: Do you think lack of transparency in institutional support is one of the key challenges? 1.Strongly Agree 2.Agree 3.Undecided 4. Disagree 5. Strongly Disagree | AK2: Do you think just financial help is NOT sufficient for business Growth? 1.Strongly Agree 2.Agree 3.Undecided 4. Disagree 5. Strongly Disagree | AL2: How frequently do you face challenges on guidance about what to do and how to do it? ( SME knowledge book for business growth) 1. Very Frequently 2. Frequently 3. Occasionally 4. Rarely 5. Never | AM2: Do you think market competition, delayed approvals, complex regulations, a competitive market, a lack of Academic institution support and a lack of government support are one of the key challenges? 1.Strongly Agree 2.Agree 3.Undecided 4. Disagree 5. Strongly Disagree | AN2: How frequently are you unable to deliver mass volume orders due to capacity issues and customer requests for ad-hoc demand? 1. Very Frequently 2. Frequently 3. Occasionally 4. Rarely 5. Never | AO2: How frequently you struggle to receive on-time payment from the Buyer and Settlement? How frequently are you unable to start the next production cycle due to non-receipt of payment from the Buyer? 1. Very Frequently 2. Frequently 3. Occasionally 4. Rarely 5. Never | AP2: Do you think Engaing local hire and give them technical training would beneficial on retaintion and digital transformation? 1.Strongly Agree 2.Agree 3.Undecided 4. Disagree 5. Strongly Disagree | AQ2: Sometimes, local hires may resist change or modern work practices, lack workplace discipline, and soft skills. Do you think limited professional skill is a hurdle to local hiring? 1.Strongly Agree 2.Agree 3.Undecided 4. Disagree 5. Strongly Disagree | AR2: Do you think local hires have similar technical skills as professional engineering resources, but only lag behind in soft skills in the context of small enterprises? 1.Strongly Agree 2.Agree 3.Undecided 4. Disagree 5. Strongly Disagree | AS2: How frequent you foresee challenges to get experienced resources for tool room ? 1. Very Frequently 2. Frequently 3. Occasionally 4. Rarely 5. Never | AT2: How frequent you foresee lack of digital skills resources? 1. Very Frequently 2. Frequently 3. Occasionally 4. Rarely 5. Never | AU2: How frequently you foresee that retaining high-skilled employees is difficult due to high salary demand? 1. Very Frequently 2. Frequently 3. Occasionally 4. Rarely 5. Never | AV2: How frequently do you face difficulties to upskill Ageing resources(Old timer) in digital technologies? 1. Very Frequently 2. Frequently 3. Occasionally 4. Rarely 5. Never
E3: KD1 | F3: KD2 | G3: KD3 | H3: KD4 | I3: KD5 | J3: KD6 | K3: KD8 | L3: KD9 | M3: KD10 | N3: KE1 | O3: KE2 | P3: KE3 | Q3: KD11 | R3: KD12 | S3: KD13 | T3: KD14 | U3: KD15 | V3: KO1 | W3: KO2 | X3: KO3 | Z3: KO4 | AA3: KO5 | AB3: KO6 | AC3: KO7 | AD3: KE4 | AE3: KE5 | AF3: KE6 | AG3: KD16 | AH3: KD17 | AI3: KD18 | AJ3: KD19 | AK3: KD20 | AL3: KD21 | AM3: KD22 | AN3: KD23 | AO3: KD24 | AP3: KE7 | AQ3: KE8 | AR3: KE9 | AS3: KD25 | AT3: KD26 | AU3: KD27 | AV3: KD28
A4: 1 | C4: Lalchand and sons | D4: Small | E4: 1987 | F4: various engineering spares for various industries | G4: Class 12 | H4: 3 | I4: 2 | J4: 2 | K4: 1 | L4: 2 | M4: 2 | N4: 1 | O4: 1 | P4: 2 | Q4: 5 | R4: 3 | S4: 2 | T4: 2 | U4: 1 | V4: 3 | W4: 2 | Y4: 18 | Z4: 3 | AA4: 2 | AB4: 1 | AC4: 1 | AD4: 1 | AE4: 1 | AF4: 2 | AG4: 4 | AH4: 2 | AI4: 1 | AJ4: 1 | AK4: 1 | AL4: 1 | AM4: 1 | AN4: 2 | AO4: 2 | AP4: 1 | AQ4: 1 | AR4: 2 | AS4: 1 | AT4: 3 | AU4: 1 | AV4: 2
A5: 2 | C5: RKMN ENTERPRISES | D5: Small | E5: 2012 | F5: Manufacturing | G5: Engineering | H5: 4 | I5: 2 | J5: 1 | K5: 2 | L5: 3 | M5: 1 | N5: 1 | O5: 1 | P5: 2 | Q5: 4 | R5: 2 | S5: 3 | T5: 1 | U5: 2 | V5: 1 | W5: 2 | Y5: 8 | Z5: 1 | AA5: 3 | AB5: 2 | AC5: 3 | AD5: 2 | AE5: 2 | AF5: 1 | AG5: 4 | AH5: 1 | AI5: 2 | AJ5: 2 | AK5: 1 | AL5: 1 | AM5: 2 | AN5: 3 | AO5: 2 | AP5: 3 | AQ5: 2 | AR5: 1 | AS5: 1 | AT5: 1 | AU5: 1 | AV5: 2
A6: 3 | C6: AUTO VENTURE | D6: Small | E6: 2021 | F6: Manufacturing | G6: Engineering | H6: 5 | I6: 2 | J6: 2 | K6: 1 | L6: 2 | M6: 2 | N6: 1 | O6: 4 | P6: 1 | Q6: 4 | R6: 2 | S6: 4 | T6: 3 | U6: 2 | V6: 2 | W6: 2 | Y6: 7 | Z6: 1 | AA6: 4 | AB6: 2 | AC6: 2 | AD6: 4 | AE6: 3 | AF6: 1 | AG6: 4 | AH6: 2 | AI6: 1 | AJ6: 2 | AK6: 2 | AL6: 1 | AM6: 2 | AN6: 2 | AO6: 3 | AP6: 3 | AQ6: 2 | AR6: 1 | AS6: 2 | AT6: 2 | AU6: 2 | AV6: 1
A7: 4 | C7: AA CRAFT @ ARCH TECH SOLUTIONS | D7: Small | E7: 2015 | F7: Manufacturing | G7: Graduation | H7: 4 | I7: 1 | J7: 2 | K7: 1 | L7: 2 | M7: 1 | N7: 2 | O7: 2 | P7: 1 | Q7: 5 | R7: 3 | S7: 2 | T7: 2 | U7: 1 | V7: 3 | W7: 2 | Y7: 10 | Z7: 2 | AA7: 2 | AB7: 1 | AC7: 2 | AD7: 2 | AE7: 2 | AF7: 1 | AG7: 4 | AH7: 1 | AI7: 2 | AJ7: 1 | AK7: 1 | AL7: 2 | AM7: 2 | AN7: 3 | AO7: 2 | AP7: 2 | AQ7: 2 | AR7: 2 | AS7: 2 | AT7: 1 | AU7: 1 | AV7: 2 | AW7: Not applicable, Donate on medical and Education for theire Employes Kids Helath and Education
A8: 5 | C8: ADYA ENTERPRISES PRIVATE LTD | D8: Small | E8: 1998 | F8: Manufacturing | G8: Graduation | H8: 4 | I8: 2 | J8: 2 | K8: 2 | L8: 1 | M8: 1 | N8: 1 | O8: 1 | P8: 2 | Q8: 4 | R8: 2 | S8: 1 | T8: 1 | U8: 2 | V8: 3 | W8: 2 | Y8: 15 | Z8: 2 | AA8: 1 | AB8: 2 | AC8: 1 | AD8: 1 | AE8: 2 | AF8: 2 | AG8: 5 | AH8: 2 | AI8: 2 | AJ8: 1 | AK8: 2 | AL8: 3 | AM8: 1 | AN8: 4 | AO8: 3 | AP8: 1 | AQ8: 1 | AR8: 2 | AS8: 2 | AT8: 3 | AU8: 1 | AV8: 3
A9: 6 | C9: AKSHAY STEEL WORKS PVT LTD | D9: Medium | E9: 1995 | F9: Manufacturing | G9: Graduation | H9: 3 | I9: 1 | J9: 2 | K9: 1 | L9: 1 | M9: 2 | N9: 1 | O9: 2 | P9: 2 | Q9: 5 | R9: 2 | S9: 3 | T9: 3 | U9: 1 | V9: 3 | W9: 2 | Y9: 17 | Z9: 3 | AA9: 3 | AB9: 1 | AC9: 1 | AD9: 1 | AE9: 2 | AF9: 2 | AG9: 4 | AH9: 3 | AI9: 1 | AJ9: 2 | AK9: 1 | AL9: 2 | AM9: 1 | AN9: 4 | AO9: 2 | AP9: 1 | AQ9: 2 | AR9: 3 | AS9: 2 | AT9: 1 | AU9: 2 | AV9: 2
A10: 7 | C10: AMAN ENTERPRISES | D10: Small | E10: 2015 | F10: Manufacturing | G10: Engineering | H10: 4 | I10: 1 | J10: 1 | K10: 1 | L10: 1 | M10: 2 | N10: 1 | O10: 2 | P10: 2 | Q10: 4 | R10: 2 | S10: 2 | T10: 2 | U10: 1 | V10: 1 | W10: 2 | Y10: 9 | Z10: 1 | AA10: 2 | AB10: 1 | AC10: 2 | AD10: 2 | AE10: 1 | AF10: 2 | AG10: 4 | AH10: 3 | AI10: 1 | AJ10: 2 | AK10: 2 | AL10: 2 | AM10: 2 | AN10: 1 | AO10: 2 | AP10: 2 | AQ10: 2 | AR10: 2 | AS10: 1 | AT10: 2 | AU10: 2 | AV10: 2
A11: 8 | C11: AMICHAND TECHNOLOGICAL PVT LTD | D11: Small | E11: 2004 | F11: Manufacturing | G11: Graduation | H11: 5 | I11: 2 | J11: 1 | K11: 2 | L11: 2 | M11: 1 | N11: 2 | O11: 3 | P11: 1 | Q11: 5 | R11: 2 | S11: 2 | T11: 2 | U11: 2 | V11: 3 | W11: 2 | Y11: 11 | Z11: 2 | AA11: 2 | AB11: 2 | AC11: 2 | AD11: 3 | AE11: 2 | AF11: 2 | AG11: 4 | AH11: 3 | AI11: 1 | AJ11: 2 | AK11: 1 | AL11: 2 | AM11: 2 | AN11: 2 | AO11: 2 | AP11: 1 | AQ11: 2 | AR11: 3 | AS11: 2 | AT11: 2 | AU11: 1 | AV11: 2
A12: 9 | C12: ANAND ENGINNERING WORKS | D12: Small | E12: 2006 | F12: Manufacturing | G12: Engineering | H12: 2 | I12: 1 | J12: 3 | K12: 1 | L12: 2 | M12: 2 | N12: 1 | O12: 2 | P12: 2 | Q12: 4 | R12: 3 | S12: 3 | T12: 1 | U12: 1 | V12: 3 | W12: 2 | Y12: 9 | Z12: 1 | AA12: 3 | AB12: 1 | AC12: 2 | AD12: 2 | AE12: 1 | AF12: 1 | AG12: 5 | AH12: 2 | AI12: 1 | AJ12: 1 | AK12: 2 | AL12: 2 | AM12: 1 | AN12: 4 | AO12: 3 | AP12: 2 | AQ12: 2 | AR12: 2 | AS12: 1 | AT12: 3 | AU12: 1 | AV12: 1
A13: 10 | C13: ANURAG ENTERPRISES | D13: Small | F13: Manufacturing | G13: NA | H13: 2 | I13: 2 | J13: 3 | K13: 3 | L13: 2 | M13: 2 | N13: 2 | O13: 2 | P13: 2 | Q13: 2 | R13: 2 | S13: 2 | T13: 1 | U13: 1 | V13: 2 | W13: 2 | Y13: 10 | Z13: 1 | AA13: 2 | AB13: 1 | AC13: 1 | AD13: 1 | AE13: 1 | AF13: 2 | AG13: 5 | AH13: 1 | AI13: 1 | AJ13: 1 | AK13: 2 | AL13: 2 | AM13: 1 | AN13: 4 | AO13: 3 | AP13: 2 | AQ13: 1 | AR13: 2 | AS13: 2 | AT13: 2 | AU13: 2 | AV13: 2
A14: 11 | C14: KUNWAR BUILDERS AND MANUFACTURERES | D14: Small | E14: 2006 | F14: Manufacturing | G14: College | H14: 2 | I14: 1 | J14: 1 | K14: 1 | L14: 1 | M14: 1 | N14: 1 | O14: 2 | P14: 2 | Q14: 3 | R14: 3 | S14: 3 | T14: 1 | U14: 2 | V14: 2 | W14: 2 | Y14: 8 | Z14: 1 | AA14: 3 | AB14: 2 | AC14: 3 | AD14: 1 | AE14: 1 | AF14: 2 | AG14: 4 | AH14: 3 | AI14: 1 | AJ14: 1 | AK14: 2 | AL14: 3 | AM14: 1 | AN14: 4 | AO14: 2 | AP14: 3 | AQ14: 2 | AR14: 3 | AS14: 1 | AT14: 3 | AU14: 2 | AV14: 1
A15: 12 | C15: INDRANI METALICS | D15: Small | E15: 2022 | F15: SHUTTER PROFILES, SHUTTER GUIDE/ CHANNEL/ SPRING PIPES | G15: Engineering | H15: 1 | I15: 1 | J15: 1 | K15: 1 | L15: 2 | M15: 3 | N15: 1 | O15: 1 | P15: 1 | Q15: 4 | R15: 2 | S15: 2 | T15: 2 | U15: 1 | V15: 3 | W15: 2 | Y15: 7 | Z15: 1 | AA15: 2 | AB15: 1 | AC15: 2 | AD15: 4 | AE15: 3 | AF15: 3 | AG15: 4 | AH15: 2 | AI15: 1 | AJ15: 2 | AK15: 1 | AL15: 2 | AM15: 2 | AN15: 4 | AO15: 2 | AP15: 2 | AQ15: 1 | AR15: 3 | AS15: 1 | AT15: 1 | AU15: 1 | AV15: 1
A16: 13 | C16: KRISHNA ENTERPRISES | D16: Small | E16: 2005 | G16: Graduation | H16: 2 | I16: 1 | J16: 1 | K16: 2 | L16: 2 | M16: 1 | N16: 1 | O16: 2 | P16: 2 | Q16: 4 | R16: 2 | S16: 2 | T16: 3 | U16: 1 | V16: 3 | W16: 2 | Y16: 10 | Z16: 1 | AA16: 2 | AB16: 1 | AC16: 2 | AD16: 2 | AE16: 3 | AF16: 2 | AG16: 5 | AH16: 1 | AI16: 1 | AJ16: 1 | AK16: 1 | AL16: 2 | AM16: 1 | AN16: 4 | AO16: 2 | AP16: 2 | AQ16: 4 | AR16: 1 | AS16: 2 | AT16: 2 | AU16: 2 | AV16: 2
A17: 14 | C17: AUTO PROFILE LTD | D17: Large | E17: 1989 | F17: Manufacturing(SHEARING, BLANKING, FORMING, BENDING, DRAW, FLANGING, PIERCING, RESTRAIKING, TRIMMING, NOTCHING, POCKET CUTTING,ETC) | G17: College | H17: 2 | I17: 3 | J17: 3 | K17: 3 | L17: 1 | M17: 1 | N17: 1 | O17: 1 | P17: 1 | Q17: 4 | R17: 3 | S17: 2 | T17: 1 | U17: 1 | V17: 3 | W17: 2 | Y17: 16 | Z17: 3 | AA17: 2 | AB17: 1 | AC17: 1 | AD17: 1 | AE17: 3 | AF17: 1 | AG17: 4 | AH17: 3 | AI17: 1 | AJ17: 2 | AK17: 1 | AL17: 3 | AM17: 2 | AN17: 4 | AO17: 3 | AP17: 3 | AQ17: 1 | AR17: 2 | AS17: 1 | AT17: 2 | AU17: 2 | AV17: 2
A18: 15 | C18: CORDOBA ENGINEERING PVT LTD | D18: Small | E18: 1991 | G18: College | H18: 2 | I18: 2 | J18: 3 | K18: 3 | L18: 1 | M18: 2 | N18: 1 | O18: 1 | P18: 2 | Q18: 4 | R18: 2 | S18: 2 | T18: 2 | U18: 1 | V18: 3 | W18: 2 | Y18: 15 | Z18: 2 | AA18: 2 | AB18: 1 | AC18: 1 | AD18: 1 | AE18: 2 | AF18: 2 | AG18: 5 | AH18: 4 | AI18: 1 | AJ18: 1 | AK18: 1 | AL18: 3 | AM18: 2 | AN18: 3 | AO18: 2 | AP18: 2 | AQ18: 2 | AR18: 1 | AS18: 1 | AT18: 2 | AU18: 3 | AV18: 2
A19: 16 | C19: JAYSHREE MOTORS PVT LTD | D19: Small | E19: 1995 | F19: DEALER OF SCOOTERS AND MOTORCYCLES | G19: Graduation | H19: 1 | I19: 2 | J19: 3 | K19: 1 | L19: 2 | M19: 2 | N19: 1 | O19: 1 | P19: 2 | Q19: 3 | R19: 3 | S19: 2 | T19: 2 | U19: 1 | V19: 1 | W19: 2 | X19: 1 | Y19: 20 | Z19: 3 | AA19: 2 | AB19: 1 | AC19: 1 | AD19: 1 | AE19: 1 | AF19: 1 | AG19: 4 | AH19: 2 | AI19: 2 | AJ19: 1 | AK19: 1 | AL19: 3 | AM19: 1 | AN19: 4 | AO19: 2 | AP19: 2 | AQ19: 2 | AR19: 2 | AS19: 2 | AT19: 1 | AU19: 3 | AV19: 3
A20: 17 | C20: SP ENGINEERING | D20: Small | E20: 1995 | G20: Graduation | H20: 1 | I20: 1 | J20: 2 | K20: 1 | L20: 1 | M20: 1 | N20: 1 | O20: 1 | P20: 1 | Q20: 2 | R20: 3 | S20: 2 | T20: 2 | U20: 1 | V20: 2 | W20: 2 | X20: 3 | Y20: 18 | Z20: 3 | AA20: 2 | AB20: 1 | AC20: 12 | AD20: 2 | AE20: 2 | AF20: 2 | AG20: 4 | AH20: 3 | AI20: 1 | AJ20: 2 | AK20: 1 | AL20: 1 | AM20: 1 | AN20: 4 | AO20: 3 | AP20: 2 | AQ20: 3 | AR20: 3 | AS20: 2 | AT20: 2 | AU20: 2 | AV20: 2
A21: 18 | C21: SK ENGINEERING | D21: Small | E21: 2008 | G21: Graduation | H21: 1 | I21: 1 | J21: 1 | K21: 1 | L21: 3 | M21: 1 | N21: 1 | O21: 1 | P21: 2 | Q21: 3 | R21: 3 | S21: 2 | T21: 2 | U21: 2 | V21: 3 | W21: 2 | X21: 3 | Y21: 8 | Z21: 1 | AA21: 2 | AB21: 2 | AC21: 1 | AD21: 1 | AE21: 1 | AF21: 2 | AG21: 5 | AH21: 2 | AI21: 2 | AJ21: 2 | AK21: 1 | AL21: 2 | AM21: 1 | AN21: 3 | AO21: 1 | AP21: 2 | AQ21: 3 | AR21: 2 | AS21: 2 | AT21: 2 | AU21: 3 | AV21: 5
A22: 19 | C22: STEEL CITY METAL PRODUCTS PVT LTD | D22: Small | E22: 1987 | F22: Automated Processes | G22: Graduation | H22: 3 | I22: 2 | J22: 3 | K22: 2 | L22: 1 | M22: 2 | N22: 1 | O22: 1 | P22: 2 | Q22: 3 | R22: 3 | S22: 2 | T22: 2 | U22: 2 | V22: 1 | W22: 2 | X22: 1 | Y22: 18 | Z22: 2 | AA22: 2 | AB22: 2 | AC22: 2 | AD22: 1 | AE22: 2 | AF22: 2 | AG22: 3 | AH22: 2 | AI22: 3 | AJ22: 4 | AK22: 2 | AL22: 2 | AM22: 3 | AN22: 3 | AO22: 4 | AP22: 2 | AQ22: 1 | AR22: 3 | AS22: 1 | AT22: 1 | AU22: 1 | AV22: 3
A23: 20 | C23: HIRANYA UDYOG | D23: Small | E23: 2010 | F23: MANUFACTURES VARIOUS TYOE OF AUTO COMPONENT BY USING CNC, VMC MACHINES AND FABRICATION WORK. | G23: Graduation | H23: 1 | I23: 2 | J23: 1 | K23: 1 | L23: 2 | M23: 2 | N23: 1 | O23: 2 | P23: 2 | Q23: 3 | R23: 3 | S23: 2 | T23: 1 | U23: 1 | V23: 2 | W23: 2 | X23: 1 | Y23: 9 | Z23: 1 | AA23: 2 | AB23: 1 | AC23: 3 | AD23: 2 | AE23: 2 | AF23: 1 | AG23: 4 | AH23: 2 | AI23: 2 | AJ23: 2 | AK23: 1 | AL23: 2 | AM23: 1 | AN23: 3 | AO23: 2 | AP23: 3 | AQ23: 2 | AR23: 2 | AS23: 2 | AT23: 2 | AU23: 1 | AV23: 3
A24: 21 | C24: PRAMANIK ABHIYANTRAN PVT LTD | D24: Small | E24: 1985 | F24: MANUFACTURES V- ROD USING CNC,VMC,VTL,MILLING PROCESS | G24: Graduation | H24: 2 | I24: 2 | J24: 2 | K24: 1 | L24: 2 | M24: 3 | N24: 1 | O24: 2 | P24: 2 | Q24: 4 | R24: 3 | S24: 2 | T24: 2 | U24: 1 | V24: 3 | W24: 2 | X24: 3 | Y24: 20 | Z24: 3 | AA24: 2 | AB24: 1 | AC24: 2 | AD24: 2 | AE24: 1 | AF24: 2 | AG24: 4 | AH24: 2 | AI24: 3 | AJ24: 2 | AK24: 1 | AL24: 2 | AM24: 1 | AN24: 3 | AO24: 2 | AP24: 3 | AQ24: 2 | AR24: 2 | AS24: 2 | AT24: 3 | AU24: 3 | AV24: 4
A25: 22 | C25: INDUSTRIAL COMPONENTS ENTERPRISES | D25: Small | E25: 1984 | F25: MANUFACTURES SPRINGS BY USING MACHINING PROCESS | G25: Graduation | H25: 2 | I25: 2 | J25: 4 | K25: 2 | L25: 1 | M25: 2 | N25: 1 | O25: 1 | P25: 1 | Q25: 3 | R25: 3 | S25: 2 | T25: 1 | U25: 1 | V25: 3 | W25: 2 | X25: 3 | Y25: 19 | Z25: 3 | AA25: 2 | AB25: 1 | AC25: 1 | AD25: 1 | AE25: 2 | AF25: 2 | AG25: 3 | AH25: 2 | AI25: 3 | AJ25: 2 | AK25: 2 | AL25: 2 | AM25: 2 | AN25: 5 | AO25: 3 | AP25: 2 | AQ25: 2 | AR25: 3 | AS25: 2 | AT25: 3 | AU25: 2 | AV25: 4
A26: 23 | C26: RKMN ENTERPRISES | D26: Small | E26: 2012 | G26: Graduation | H26: 3 | I26: 1 | J26: 1 | K26: 1 | L26: 4 | M26: 1 | N26: 1 | O26: 1 | P26: 1 | Q26: 3 | R26: 3 | S26: 1 | T26: 2 | U26: 1 | V26: 1 | W26: 2 | X26: 1 | Y26: 8 | Z26: 1 | AA26: 1 | AB26: 1 | AC26: 2 | AD26: 1 | AE26: 2 | AF26: 2 | AG26: 4 | AH26: 2 | AI26: 2 | AJ26: 2 | AK26: 1 | AL26: 1 | AM26: 3 | AN26: 5 | AO26: 2 | AP26: 2 | AQ26: 2 | AR26: 3 | AS26: 2 | AT26: 3 | AU26: 4 | AV26: 2
A27: 24 | C27: IPSG PVT LTD | D27: Small | E27: 1995 | F27: MANUFACTURES SPARE PARTS USING MACHINING PROCESS. | H27: 4 | I27: 2 | J27: 3 | K27: 2 | L27: 2 | M27: 2 | N27: 1 | O27: 1 | P27: 2 | Q27: 2 | R27: 2 | S27: 2 | T27: 2 | U27: 1 | V27: 3 | W27: 2 | X27: 3 | Y27: 17 | Z27: 3 | AA27: 2 | AB27: 1 | AC27: 2 | AD27: 1 | AE27: 2 | AF27: 2 | AG27: 3 | AH27: 2 | AI27: 1 | AJ27: 1 | AK27: 1 | AL27: 2 | AM27: 2 | AN27: 4 | AO27: 4 | AP27: 3 | AQ27: 3 | AR27: 1 | AS27: 4 | AT27: 4 | AU27: 5 | AV27: 2
A28: 25 | C28: S.S.S MEHTA ENTERPRISES INDUSTRIES PVT LTD UNIT-1 | D28: Small | E28: 2012 | F28: MANUFACTURES AUTO COMPONENTS PARTS, SHEET METAL WORKS, ETC BY USING MACHINING, WELDING, BENDING, CUTTING PROCESSESS. | G28: Graduation | H28: 3 | I28: 1 | J28: 4 | K28: 2 | L28: 3 | M28: 1 | N28: 1 | O28: 2 | P28: 1 | Q28: 3 | R28: 2 | S28: 2 | T28: 1 | U28: 1 | V28: 3 | W28: 2 | X28: 3 | Y28: 8 | Z28: 1 | AA28: 2 | AB28: 1 | AC28: 2 | AD28: 3 | AE28: 2 | AF28: 2 | AG28: 4 | AH28: 2 | AI28: 2 | AJ28: 3 | AK28: 1 | AL28: 2 | AM28: 2 | AN28: 5 | AO28: 2 | AP28: 2 | AQ28: 1 | AR28: 1 | AS28: 2 | AT28: 3 | AU28: 2 | AV28: 4
A29: 26 | C29: DILIP PRESS METAL & AGROTECH PVT LTD | D29: Small | E29: 1973 | F29: MANUFACTURES SHEET METAL AUTO COMPONENTS BY USING FABRICATION PROCESS. | G29: Graduation | H29: 3 | I29: 2 | J29: 2 | K29: 2 | L29: 1 | M29: 3 | N29: 2 | O29: 1 | P29: 2 | Q29: 3 | R29: 3 | S29: 3 | T29: 2 | U29: 2 | V29: 3 | W29: 2 | X29: 3 | Y29: 21 | Z29: 4 | AA29: 3 | AB29: 2 | AC29: 1 | AD29: 1 | AE29: 2 | AF29: 2 | AG29: 4 | AH29: 2 | AI29: 3 | AJ29: 3 | AK29: 2 | AL29: 2 | AM29: 2 | AN29: 5 | AO29: 4 | AP29: 2 | AQ29: 3 | AR29: 3 | AS29: 4 | AT29: 3 | AU29: 4 | AV29: 2
A30: 27 | C30: P D FORGE PVT LTD | D30: Small | E30: 1992 | H30: 3 | I30: 2 | J30: 2 | K30: 2 | L30: 2 | M30: 2 | N30: 2 | O30: 2 | P30: 2 | Q30: 3 | R30: 2 | S30: 2 | T30: 2 | U30: 2 | V30: 3 | W30: 2 | X30: 3 | Y30: 15 | Z30: 2 | AA30: 2 | AB30: 2 | AC30: 2 | AD30: 2 | AE30: 2 | AF30: 2 | AG30: 5 | AH30: 2 | AI30: 1 | AJ30: 2 | AK30: 3 | AL30: 2 | AM30: 4 | AN30: 4 | AO30: 2 | AP30: 1 | AQ30: 2 | AR30: 3 | AS30: 4 | AT30: 3 | AU30: 3 | AV30: 4
A31: 28 | C31: SANDHYA ENGINEERING | D31: Small | E31: 2008 | F31: DOES JOB WORK AND MANUFACTURES R.A SHAFTS AND AXEL PARTS BY USING MACHINING PROCESS. | G31: bsc | H31: 4 | I31: 1 | J31: 2 | K31: 1 | L31: 1 | M31: 2 | N31: 2 | O31: 2 | P31: 2 | Q31: 3 | R31: 1 | S31: 1 | T31: 2 | U31: 1 | V31: 3 | W31: 2 | X31: 3 | Y31: 8 | Z31: 1 | AA31: 1 | AB31: 1 | AC31: 2 | AD31: 1 | AE31: 1 | AF31: 2 | AG31: 2 | AH31: 2 | AI31: 2 | AJ31: 2 | AK31: 1 | AL31: 1 | AM31: 2 | AN31: 2 | AO31: 2 | AP31: 2 | AQ31: 3 | AR31: 1 | AS31: 1 | AT31: 2 | AU31: 1 | AV31: 2
A32: 29 | C32: AURO PLASTIC INJECTION MOULDING | D32: Smal | E32: 1996 | F32: MANUFACTRURES PLASTIC AUTOMOTIVE PARTS BY USING INJECTION MOULDING PROCESS. | G32: NA | H32: 3 | I32: 2 | J32: 4 | K32: 2 | L32: 2 | M32: 1 | N32: 1 | O32: 1 | P32: 1 | Q32: 3 | R32: 2 | S32: 2 | T32: 1 | U32: 2 | V32: 3 | W32: 1 | X32: 3 | Y32: 20 | Z32: 4 | AA32: 2 | AB32: 2 | AC32: 1 | AD32: 1 | AE32: 2 | AF32: 2 | AG32: 2 | AH32: 2 | AI32: 1 | AJ32: 2 | AK32: 2 | AL32: 1 | AM32: 2 | AN32: 3 | AO32: 2 | AP32: 2 | AQ32: 2 | AR32: 1 | AS32: 2 | AT32: 3 | AU32: 2 | AV32: 4
A33: 30 | C33: ROY BROTHERS | D33: Small | E33: 1981 | G33: NA | H33: 4 | I33: 2 | J33: 3 | K33: 2 | L33: 1 | M33: 3 | N33: 1 | O33: 1 | P33: 2 | Q33: 3 | R33: 2 | S33: 2 | T33: 2 | U33: 2 | V33: 2 | W33: 2 | X33: 3 | Y33: 19 | Z33: 3 | AA33: 2 | AB33: 2 | AC33: 2 | AD33: 1 | AE33: 2 | AF33: 2 | AG33: 4 | AH33: 2 | AI33: 2 | AJ33: 1 | AK33: 3 | AL33: 2 | AM33: 2 | AN33: 3 | AO33: 2 | AP33: 2 | AQ33: 1 | AR33: 3 | AS33: 2 | AT33: 2 | AU33: 3 | AV33: 4
A34: 31 | C34: SUMIT ENTERPRISES | D34: Small | E34: 1987 | G34: Graduation | H34: 4 | I34: 2 | J34: 3 | K34: 2 | L34: 3 | M34: 3 | N34: 2 | O34: 2 | P34: 3 | Q34: 2 | R34: 2 | S34: 2 | T34: 2 | U34: 2 | V34: 3 | W34: 2 | X34: 3 | Y34: 16 | Z34: 3 | AA34: 2 | AB34: 2 | AC34: 2 | AD34: 2 | AE34: 2 | AF34: 2 | AG34: 2 | AH34: 3 | AI34: 3 | AJ34: 4 | AK34: 2 | AL34: 2 | AM34: 3 | AN34: 3 | AO34: 2 | AP34: 2 | AQ34: 2 | AR34: 3 | AS34: 4 | AT34: 3 | AU34: 4 | AV34: 3
A35: 32 | C35: BHARAT AUTO WORKS | D35: Small | E35: 2000 | H35: 4 | I35: 2 | J35: 3 | K35: 3 | L35: 3 | M35: 2 | N35: 3 | O35: 4 | P35: 3 | Q35: 2 | R35: 3 | S35: 2 | T35: 3 | U35: 3 | V35: 3 | W35: 2 | X35: 3 | Y35: 8 | Z35: 1 | AA35: 2 | AB35: 3 | AC35: 2 | AD35: 4 | AE35: 2 | AF35: 4 | AG35: 4 | AH35: 3 | AI35: 2 | AJ35: 4 | AK35: 3 | AL35: 3 | AM35: 3 | AN35: 4 | AO35: 2 | AP35: 3 | AQ35: 2 | AR35: 3 | AS35: 3 | AT35: 3 | AU35: 4 | AV35: 3
A36: 33 | C36: SWASTIK ENTERPRISES | D36: Small | E36: 2008 | H36: 4 | I36: 3 | J36: 3 | K36: 2 | L36: 3 | M36: 3 | N36: 2 | O36: 2 | P36: 3 | Q36: 3 | R36: 2 | S36: 2 | T36: 2 | U36: 2 | V36: 2 | W36: 2 | X36: 3 | Y36: 9 | Z36: 1 | AA36: 2 | AB36: 2 | AC36: 3 | AD36: 2 | AE36: 2 | AF36: 1 | AG36: 4 | AH36: 2 | AI36: 2 | AJ36: 4 | AK36: 2 | AL36: 2 | AM36: 2 | AN36: 4 | AO36: 3 | AP36: 3 | AQ36: 2 | AR36: 2 | AS36: 3 | AT36: 2 | AU36: 3 | AV36: 2
A37: 34 | C37: KARMAKAR ENTERPRISES | D37: Small | E37: 2021 | H37: 5 | I37: 2 | J37: 2 | K37: 3 | L37: 2 | M37: 2 | N37: 3 | O37: 4 | P37: 3 | Q37: 2 | R37: 3 | S37: 2 | T37: 2 | U37: 3 | V37: 2 | W37: 2 | X37: 4 | Y37: 7 | Z37: 1 | AA37: 2 | AB37: 3 | AC37: 1 | AD37: 3 | AE37: 2 | AF37: 2 | AG37: 4 | AH37: 3 | AI37: 2 | AJ37: 3 | AK37: 3 | AL37: 2 | AM37: 2 | AN37: 3 | AO37: 2 | AP37: 3 | AQ37: 3 | AR37: 2 | AS37: 3 | AT37: 4 | AU37: 2 | AV37: 3
A38: 35 | C38: HI-TECH TOOLS & FIXTURES | D38: Small | E38: 2010 | H38: 4 | I38: 1 | J38: 1 | K38: 1 | L38: 4 | M38: 1 | N38: 2 | O38: 2 | P38: 1 | Q38: 3 | R38: 2 | S38: 3 | T38: 2 | U38: 2 | V38: 2 | W38: 2 | X38: 1 | Y38: 8 | Z38: 1 | AA38: 3 | AB38: 2 | AC38: 2 | AD38: 2 | AE38: 2 | AF38: 2 | AG38: 4 | AH38: 2 | AI38: 2 | AJ38: 3 | AK38: 2 | AL38: 1 | AM38: 2 | AN38: 4 | AO38: 2 | AP38: 3 | AQ38: 2 | AR38: 3 | AS38: 2 | AT38: 2 | AU38: 3 | AV38: 2
A39: 36 | C39: OMEGA AUTOMOTIVE PVT LTD | D39: Small | E39: 2014 | H39: 4 | I39: 2 | J39: 2 | K39: 2 | L39: 4 | M39: 1 | N39: 1 | O39: 1 | P39: 2 | Q39: 3 | R39: 2 | S39: 2 | T39: 2 | U39: 2 | V39: 1 | W39: 2 | X39: 4 | Y39: 9 | Z39: 1 | AA39: 2 | AB39: 2 | AC39: 2 | AD39: 1 | AE39: 1 | AF39: 1 | AG39: 4 | AH39: 2 | AI39: 1 | AJ39: 2 | AK39: 2 | AL39: 2 | AM39: 3 | AN39: 2 | AO39: 1 | AP39: 3 | AQ39: 3 | AR39: 3 | AS39: 3 | AT39: 2 | AU39: 3 | AV39: 4
A40: 37 | C40: G-LOK FLUID CONNECTORS | D40: Small | E40: 2015 | H40: 4 | I40: 2 | J40: 1 | K40: 2 | L40: 2 | M40: 1 | N40: 1 | O40: 2 | P40: 2 | Q40: 2 | R40: 2 | S40: 3 | T40: 1 | U40: 3 | V40: 1 | W40: 2 | X40: 4 | Y40: 9 | Z40: 1 | AA40: 3 | AB40: 3 | AC40: 2 | AD40: 2 | AE40: 2 | AF40: 2 | AG40: 3 | AH40: 2 | AI40: 2 | AJ40: 2 | AK40: 1 | AL40: 1 | AM40: 1 | AN40: 2 | AO40: 1 | AP40: 3 | AQ40: 3 | AR40: 2 | AS40: 2 | AT40: 1 | AU40: 2 | AV40: 2
...

Sheet Method
B2: Importance Factor Score | C2: Adjusted Score
B3: 0-0.25 | C3: 1
B4: 0.26-0.50 | C4: 2
B5: 0.51-0.83 | C5: 3
B6: 0.83-1.10 | C6: 4
B7: 1.11 + | C7: 5
B9: KEY DIMENSION (Likert) | C9: Avg Dim Score | D9: Imp Factor Score | E9: Adjusted Score
B10: Buy process,Demand Planning & Procurement | C10: 2.289604 | D10: =3-C10 -> 0.71039604 | E10: 3
B11: Current Operational Process , Legacy & new machine to balance | C11: 2.1818182 | D11: =3-C11 -> 0.81818182 | E11: 3
B12: Effortable Digital technologies | C12: 1.5346535 | D12: =3-C12 -> 1.4653465 | E12: 5
B13: Owner's viewpoints | C13: 2.1069307 | D13: =3-C13 -> 0.89306931 | E13: 4
B14: Growth and Effeciency.Challenges to penetrate the global market. | C14: 1.8085809 | D14: =3-C14 -> 1.1914191 | E14: 5
B15: Certification &Standarization | C15: 1.7788779 | D15: =3-C15 -> 1.2211221 | E15: 5
B16: Financial challenges ,lack of transparency in institutional support , and knowledge gap on Ecosystem Integration | C16: 2.2607261 | D16: =3-C16 -> 0.73927393 | E16: 3
B17: Administrative , Operational challenges & Eco system Integration challenges | C17: 2.5808581 | D17: =3-C17 -> 0.41914191 | E17: 2
B18: Engaging local hire | C18: 2.2013201 | D18: =3-C18 -> 0.79867987 | E18: 3
B19: Skill Gap ,Retaining resources and workforce Management | C19: 2.1582426 | D19: =3-C19 -> 0.84175743 | E19: 4
B21: KEY DIMENSION (Likert) | C21: Mode | D21: Mode Freq | E21: Total Data Points | F21: %Mode Freq | G21: Adjusted Score
B22: Current Operational Process , Legacy & new machine to balance | C22: =MODE(Data_survey!M4:M104) -> 1 | D22: =COUNTIF(Data_survey!M4:M104,1) -> 51 | E22: =COUNT(Data_survey!M4:M104) -> 101 | F22: =D22/E22 -> 0.5049505 | G22: 3
B23: Growth and Effeciency.Challenges to penetrate the global market. (V) | C23: =MODE(Data_survey!V4:V104) -> 3 | D23: =COUNTIF(Data_survey!V4:V104,3) -> 55 | E23: =COUNT(Data_survey!V4:V104) -> 100 | F23: =D23/E23 -> 0.55 | G23: NA
B24: Growth and Effeciency.Challenges to penetrate the global market. (W) | C24: =MODE(Data_survey!W4:W104) -> 2 | D24: =COUNTIF(Data_survey!W4:W104,2) -> 99 | E24: =COUNT(Data_survey!W4:W104) -> 101 | F24: =D24/E24 -> 0.98019802 | G24: NA
B25: Growth and Effeciency.Challenges to penetrate the global market. (X) | C25: =MODE(Data_survey!X19:X104) -> 3 | D25: =COUNTIF(Data_survey!X19:X104,3) -> 49 | E25: =COUNT(Data_survey!X4:X104) -> 85 | F25: =D25/E25 -> 0.57647059 | G25: NA
B26: Growth and Effeciency.Challenges to penetrate the global market. (Z) | C26: =MODE(Data_survey!Z4:Z104) -> 1 | D26: =COUNTIF(Data_survey!Z4:Z104,1) -> 47 | E26: =COUNT(Data_survey!Z4:Z104) -> 101 | F26: =D26/E26 -> 0.46534653 | G26: NA
B27: Growth and Effeciency.Challenges to penetrate the global market. (Final) | C27: NA | D27: NA | E27: NA | F27: =AVERAGE(F23:F26) -> 0.64300379 | G27: 4

Sheet Importance Mapping
A1: KEY DIMENSION | B1: Adjusted Importance Score | C1: IMPORTANCE POINTS (Knowledge based) | D1: FINAL WEIGHTAGE
A2: Buy process,Demand Planning & Procurement | B2: 3 | C2: 0 | D2: =IF(C2=0,B2,AVERAGE(B2,C2)) -> 3
A3: Current Operational Process , Legacy & new machine to balance | B3: 3 | C3: 3 | D3: =IF(C3=0,B3,AVERAGE(B3,C3)) -> 3
A4: Effortable Digital technologies | B4: 5 | C4: 0 | D4: =IF(C4=0,B4,AVERAGE(B4,C4)) -> 5
A5: Owner's viewpoints | B5: 4 | C5: 0 | D5: =IF(C5=0,B5,AVERAGE(B5,C5)) -> 4
A6: Growth and Effeciency.Challenges to penetrate the global market. | B6: 5 | C6: 4 | D6: =IF(C6=0,B6,AVERAGE(B6,C6)) -> 4.5
A7: Certification &Standarization | B7: 5 | C7: 0 | D7: =IF(C7=0,B7,AVERAGE(B7,C7)) -> 5
A8: Financial challenges ,lack of transparency in institutional support , and knowledge gap on Ecosystem Integration | B8: 3 | C8: 0 | D8: =IF(C8=0,B8,AVERAGE(B8,C8)) -> 3
A9: Administrative , Operational challenges & Eco system Integration challenges | B9: 2 | C9: 0 | D9: =IF(C9=0,B9,AVERAGE(B9,C9)) -> 2
A10: Engaging local hire | B10: 3 | C10: 0 | D10: =IF(C10=0,B10,AVERAGE(B10,C10)) -> 3
A11: Skill Gap ,Retaining resources and workforce Management | B11: 4 | C11: 0 | D11: =IF(C11=0,B11,AVERAGE(B11,C11)) -> 4

Sheet Relative Imp Matrix
A1: Relative Importance of Dimensions Matrix
B2: Buy process,Demand Planning & Procurement | C2: Current Operational Process , Legacy & new machine to balance | D2: Effortable Digital technologies | E2: Owner's viewpoints | F2: Growth and Effeciency.Challenges to penetrate the global market. | G2: Certification &Standarization | H2: Financial challenges ,lack of transparency in institutional support , and knowledge gap on Ecosystem Integration | I2: Administrative , Operational challenges & Eco system Integration challenges | J2: Engaging local hire | K2: Skill Gap ,Retaining resources and workforce Management
A3: Buy process,Demand Planning & Procurement | B3: ='Importance Mapping'!D2/'Importance Mapping'!$D$2 -> 1 | C3: ='Importance Mapping'!D2/'Importance Mapping'!$D$3 -> 1 | D3: ='Importance Mapping'!D2/'Importance Mapping'!$D$4 -> 0.6 | E3: ='Importance Mapping'!D2/'Importance Mapping'!$D$5 -> 0.75 | F3: ='Importance Mapping'!D2/'Importance Mapping'!$D$6 -> 0.66666667 | G3: ='Importance Mapping'!D2/'Importance Mapping'!$D$7 -> 0.6 | H3: ='Importance Mapping'!D2/'Importance Mapping'!$D$8 -> 1 | I3: ='Importance Mapping'!D2/'Importance Mapping'!$D$9 -> 1.5 | J3: ='Importance Mapping'!D2/'Importance Mapping'!$D$10 -> 1 | K3: ='Importance Mapping'!D2/'Importance Mapping'!$D$11 -> 0.75
A4: Current Operational Process , Legacy & new machine to balance | B4: ='Importance Mapping'!D3/'Importance Mapping'!$D$2 -> 1 | C4: ='Importance Mapping'!D3/'Importance Mapping'!$D$3 -> 1 | D4: ='Importance Mapping'!D3/'Importance Mapping'!$D$4 -> 0.6 | E4: ='Importance Mapping'!D3/'Importance Mapping'!$D$5 -> 0.75 | F4: ='Importance Mapping'!D3/'Importance Mapping'!$D$6 -> 0.66666667 | G4: ='Importance Mapping'!D3/'Importance Mapping'!$D$7 -> 0.6 | H4: ='Importance Mapping'!D3/'Importance Mapping'!$D$8 -> 1 | I4: ='Importance Mapping'!D3/'Importance Mapping'!$D$9 -> 1.5 | J4: ='Importance Mapping'!D3/'Importance Mapping'!$D$10 -> 1 | K4: ='Importance Mapping'!D3/'Importance Mapping'!$D$11 -> 0.75
A5: Effortable Digital technologies | B5: ='Importance Mapping'!D4/'Importance Mapping'!$D$2 -> 1.6666667 | C5: ='Importance Mapping'!D4/'Importance Mapping'!$D$3 -> 1.6666667 | D5: ='Importance Mapping'!D4/'Importance Mapping'!$D$4 -> 1 | E5: ='Importance Mapping'!D4/'Importance Mapping'!$D$5 -> 1.25 | F5: ='Importance Mapping'!D4/'Importance Mapping'!$D$6 -> 1.1111111 | G5: ='Importance Mapping'!D4/'Importance Mapping'!$D$7 -> 1 | H5: ='Importance Mapping'!D4/'Importance Mapping'!$D$8 -> 1.6666667 | I5: ='Importance Mapping'!D4/'Importance Mapping'!$D$9 -> 2.5 | J5: ='Importance Mapping'!D4/'Importance Mapping'!$D$10 -> 1.6666667 | K5: ='Importance Mapping'!D4/'Importance Mapping'!$D$11 -> 1.25
A6: Owner's viewpoints | B6: ='Importance Mapping'!D5/'Importance Mapping'!$D$2 -> 1.3333333 | C6: ='Importance Mapping'!D5/'Importance Mapping'!$D$3 -> 1.3333333 | D6: ='Importance Mapping'!D5/'Importance Mapping'!$D$4 -> 0.8 | E6: ='Importance Mapping'!D5/'Importance Mapping'!$D$5 -> 1 | F6: ='Importance Mapping'!D5/'Importance Mapping'!$D$6 -> 0.88888889 | G6: ='Importance Mapping'!D5/'Importance Mapping'!$D$7 -> 0.8 | H6: ='Importance Mapping'!D5/'Importance Mapping'!$D$8 -> 1.3333333 | I6: ='Importance Mapping'!D5/'Importance Mapping'!$D$9 -> 2 | J6: ='Importance Mapping'!D5/'Importance Mapping'!$D$10 -> 1.3333333 | K6: ='Importance Mapping'!D5/'Importance Mapping'!$D$11 -> 1
A7: Growth and Effeciency.Challenges to penetrate the global market. | B7: ='Importance Mapping'!D6/'Importance Mapping'!$D$2 -> 1.5 | C7: ='Importance Mapping'!D6/'Importance Mapping'!$D$3 -> 1.5 | D7: ='Importance Mapping'!D6/'Importance Mapping'!$D$4 -> 0.9 | E7: ='Importance Mapping'!D6/'Importance Mapping'!$D$5 -> 1.125 | F7: ='Importance Mapping'!D6/'Importance Mapping'!$D$6 -> 1 | G7: ='Importance Mapping'!D6/'Importance Mapping'!$D$7 -> 0.9 | H7: ='Importance Mapping'!D6/'Importance Mapping'!$D$8 -> 1.5 | I7: ='Importance Mapping'!D6/'Importance Mapping'!$D$9 -> 2.25 | J7: ='Importance Mapping'!D6/'Importance Mapping'!$D$10 -> 1.5 | K7: ='Importance Mapping'!D6/'Importance Mapping'!$D$11 -> 1.125
A8: Certification &Standarization | B8: ='Importance Mapping'!D7/'Importance Mapping'!$D$2 -> 1.6666667 | C8: ='Importance Mapping'!D7/'Importance Mapping'!$D$3 -> 1.6666667 | D8: ='Importance Mapping'!D7/'Importance Mapping'!$D$4 -> 1 | E8: ='Importance Mapping'!D7/'Importance Mapping'!$D$5 -> 1.25 | F8: ='Importance Mapping'!D7/'Importance Mapping'!$D$6 -> 1.1111111 | G8: ='Importance Mapping'!D7/'Importance Mapping'!$D$7 -> 1 | H8: ='Importance Mapping'!D7/'Importance Mapping'!$D$8 -> 1.6666667 | I8: ='Importance Mapping'!D7/'Importance Mapping'!$D$9 -> 2.5 | J8: ='Importance Mapping'!D7/'Importance Mapping'!$D$10 -> 1.6666667 | K8: ='Importance Mapping'!D7/'Importance Mapping'!$D$11 -> 1.25
A9: Financial challenges ,lack of transparency in institutional support , and knowledge gap on Ecosystem Integration | B9: ='Importance Mapping'!D8/'Importance Mapping'!$D$2 -> 1 | C9: ='Importance Mapping'!D8/'Importance Mapping'!$D$3 -> 1 | D9: ='Importance Mapping'!D8/'Importance Mapping'!$D$4 -> 0.6 | E9: ='Importance Mapping'!D8/'Importance Mapping'!$D$5 -> 0.75 | F9: ='Importance Mapping'!D8/'Importance Mapping'!$D$6 -> 0.66666667 | G9: ='Importance Mapping'!D8/'Importance Mapping'!$D$7 -> 0.6 | H9: ='Importance Mapping'!D8/'Importance Mapping'!$D$8 -> 1 | I9: ='Importance Mapping'!D8/'Importance Mapping'!$D$9 -> 1.5 | J9: ='Importance Mapping'!D8/'Importance Mapping'!$D$10 -> 1 | K9: ='Importance Mapping'!D8/'Importance Mapping'!$D$11 -> 0.75
A10: Administrative , Operational challenges & Eco system Integration challenges | B10: ='Importance Mapping'!D9/'Importance Mapping'!$D$2 -> 0.66666667 | C10: ='Importance Mapping'!D9/'Importance Mapping'!$D$3 -> 0.66666667 | D10: ='Importance Mapping'!D9/'Importance Mapping'!$D$4 -> 0.4 | E10: ='Importance Mapping'!D9/'Importance Mapping'!$D$5 -> 0.5 | F10: ='Importance Mapping'!D9/'Importance Mapping'!$D$6 -> 0.44444444 | G10: ='Importance Mapping'!D9/'Importance Mapping'!$D$7 -> 0.4 | H10: ='Importance Mapping'!D9/'Importance Mapping'!$D$8 -> 0.66666667 | I10: ='Importance Mapping'!D9/'Importance Mapping'!$D$9 -> 1 | J10: ='Importance Mapping'!D9/'Importance Mapping'!$D$10 -> 0.66666667 | K10: ='Importance Mapping'!D9/'Importance Mapping'!$D$11 -> 0.5
A11: Engaging local hire | B11: ='Importance Mapping'!D10/'Importance Mapping'!$D$2 -> 1 | C11: ='Importance Mapping'!D10/'Importance Mapping'!$D$3 -> 1 | D11: ='Importance Mapping'!D10/'Importance Mapping'!$D$4 -> 0.6 | E11: ='Importance Mapping'!D10/'Importance Mapping'!$D$5 -> 0.75 | F11: ='Importance Mapping'!D10/'Importance Mapping'!$D$6 -> 0.66666667 | G11: ='Importance Mapping'!D10/'Importance Mapping'!$D$7 -> 0.6 | H11: ='Importance Mapping'!D10/'Importance Mapping'!$D$8 -> 1 | I11: ='Importance Mapping'!D10/'Importance Mapping'!$D$9 -> 1.5 | J11: ='Importance Mapping'!D10/'Importance Mapping'!$D$10 -> 1 | K11: ='Importance Mapping'!D10/'Importance Mapping'!$D$11 -> 0.75
A12: Skill Gap ,Retaining resources and workforce Management | B12: ='Importance Mapping'!D11/'Importance Mapping'!$D$2 -> 1.3333333 | C12: ='Importance Mapping'!D11/'Importance Mapping'!$D$3 -> 1.3333333 | D12: ='Importance Mapping'!D11/'Importance Mapping'!$D$4 -> 0.8 | E12: ='Importance Mapping'!D11/'Importance Mapping'!$D$5 -> 1 | F12: ='Importance Mapping'!D11/'Importance Mapping'!$D$6 -> 0.88888889 | G12: ='Importance Mapping'!D11/'Importance Mapping'!$D$7 -> 0.8 | H12: ='Importance Mapping'!D11/'Importance Mapping'!$D$8 -> 1.3333333 | I12: ='Importance Mapping'!D11/'Importance Mapping'!$D$9 -> 2 | J12: ='Importance Mapping'!D11/'Importance Mapping'!$D$10 -> 1.3333333 | K12: ='Importance Mapping'!D11/'Importance Mapping'!$D$11 -> 1
A13: SUM | B13: =SUM(B3:B12) -> 12.166667 | C13: =SUM(C3:C12) -> 12.166667 | D13: =SUM(D3:D12) -> 7.3 | E13: =SUM(E3:E12) -> 9.125 | F13: =SUM(F3:F12) -> 8.1111111 | G13: =SUM(G3:G12) -> 7.3 | H13: =SUM(H3:H12) -> 12.166667 | I13: =SUM(I3:I12) -> 18.25 | ... K13: =SUM(K3:K12) -> 9.125
A15: Weighted Matrix v Total
B16: Buy process,Demand Planning & Procurement | C16: Current Operational Process , Legacy & new machine to balance | D16: Effortable Digital technologies | E16: Owner's viewpoints | F16: Growth and Effeciency.Challenges to penetrate the global market. | G16: Certification &Standarization | H16: Financial challenges ,lack of transparency in institutional support , and knowledge gap on Ecosystem Integration | I16: Administrative , Operational challenges & Eco system Integration challenges | J16: Engaging local hire | K16: Skill Gap ,Retaining resources and workforce Management | L16: AVERAGE
A17: Buy process,Demand Planning & Procurement | B17: =B3/$B$13 -> 0.082191781 | C17: =C3/$C$13 -> 0.082191781 | D17: =D3/$D$13 -> 0.082191781 | E17: =E3/$E$13 -> 0.082191781 | F17: =F3/$F$13 -> 0.082191781 | G17: =G3/$G$13 -> 0.082191781 | H17: =H3/$H$13 -> 0.082191781 | I17: =I3/$I$13 -> 0.082191781 | J17: =J3/$J$13 -> 0.082191781 | K17: =K3/$K$13 -> 0.082191781 | L17: =AVERAGE(B17:K17) -> 0.082191781
A18: Current Operational Process , Legacy & new machine to balance | B18: =B4/$B$13 -> 0.082191781 | C18: =C4/$C$13 -> 0.082191781 | D18: =D4/$D$13 -> 0.082191781 | E18: =E4/$E$13 -> 0.082191781 | F18: =F4/$F$13 -> 0.082191781 | G18: =G4/$G$13 -> 0.082191781 | H18: =H4/$H$13 -> 0.082191781 | I18: =I4/$I$13 -> 0.082191781 | J18: =J4/$J$13 -> 0.082191781 | K18: =K4/$K$13 -> 0.082191781 | L18: =AVERAGE(B18:K18) -> 0.082191781
A19: Effortable Digital technologies | B19: =B5/$B$13 -> 0.1369863 | C19: =C5/$C$13 -> 0.1369863 | D19: =D5/$D$13 -> 0.1369863 | E19: =E5/$E$13 -> 0.1369863 | F19: =F5/$F$13 -> 0.1369863 | G19: =G5/$G$13 -> 0.1369863 | H19: =H5/$H$13 -> 0.1369863 | I19: =I5/$I$13 -> 0.1369863 | J19: =J5/$J$13 -> 0.1369863 | K19: =K5/$K$13 -> 0.1369863 | L19: =AVERAGE(B19:K19) -> 0.1369863 | M19: Most
A20: Owner's viewpoints | B20: =B6/$B$13 -> 0.10958904 | C20: =C6/$C$13 -> 0.10958904 | D20: =D6/$D$13 -> 0.10958904 | E20: =E6/$E$13 -> 0.10958904 | F20: =F6/$F$13 -> 0.10958904 | G20: =G6/$G$13 -> 0.10958904 | H20: =H6/$H$13 -> 0.10958904 | I20: =I6/$I$13 -> 0.10958904 | J20: =J6/$J$13 -> 0.10958904 | K20: =K6/$K$13 -> 0.10958904 | L20: =AVERAGE(B20:K20) -> 0.10958904
A21: Growth and Effeciency.Challenges to penetrate the global market. | B21: =B7/$B$13 -> 0.12328767 | C21: =C7/$C$13 -> 0.12328767 | D21: =D7/$D$13 -> 0.12328767 | E21: =E7/$E$13 -> 0.12328767 | F21: =F7/$F$13 -> 0.12328767 | G21: =G7/$G$13 -> 0.12328767 | H21: =H7/$H$13 -> 0.12328767 | I21: =I7/$I$13 -> 0.12328767 | J21: =J7/$J$13 -> 0.12328767 | K21: =K7/$K$13 -> 0.12328767 | L21: =AVERAGE(B21:K21) -> 0.12328767
A22: Certification &Standarization | B22: =B8/$B$13 -> 0.1369863 | C22: =C8/$C$13 -> 0.1369863 | D22: =D8/$D$13 -> 0.1369863 | E22: =E8/$E$13 -> 0.1369863 | F22: =F8/$F$13 -> 0.1369863 | G22: =G8/$G$13 -> 0.1369863 | H22: =H8/$H$13 -> 0.1369863 | I22: =I8/$I$13 -> 0.1369863 | J22: =J8/$J$13 -> 0.1369863 | K22: =K8/$K$13 -> 0.1369863 | L22: =AVERAGE(B22:K22) -> 0.1369863 | M22: Most
A23: Financial challenges ,lack of transparency in institutional support , and knowledge gap on Ecosystem Integration | B23: =B9/$B$13 -> 0.082191781 | C23: =C9/$C$13 -> 0.082191781 | D23: =D9/$D$13 -> 0.082191781 | E23: =E9/$E$13 -> 0.082191781 | F23: =F9/$F$13 -> 0.082191781 | G23: =G9/$G$13 -> 0.082191781 | H23: =H9/$H$13 -> 0.082191781 | I23: =I9/$I$13 -> 0.082191781 | J23: =J9/$J$13 -> 0.082191781 | K23: =K9/$K$13 -> 0.082191781 | L23: =AVERAGE(B23:K23) -> 0.082191781
A24: Administrative , Operational challenges & Eco system Integration challenges | B24: =B10/$B$13 -> 0.054794521 | C24: =C10/$C$13 -> 0.054794521 | D24: =D10/$D$13 -> 0.054794521 | E24: =E10/$E$13 -> 0.054794521 | F24: =F10/$F$13 -> 0.054794521 | G24: =G10/$G$13 -> 0.054794521 | H24: =H10/$H$13 -> 0.054794521 | I24: =I10/$I$13 -> 0.054794521 | J24: =J10/$J$13 -> 0.054794521 | K24: =K10/$K$13 -> 0.054794521 | L24: =AVERAGE(B24:K24) -> 0.054794521 | M24: Least
A25: Engaging local hire | B25: =B11/$B$13 -> 0.082191781 | C25: =C11/$C$13 -> 0.082191781 | D25: =D11/$D$13 -> 0.082191781 | E25: =E11/$E$13 -> 0.082191781 | F25: =F11/$F$13 -> 0.082191781 | G25: =G11/$G$13 -> 0.082191781 | H25: =H11/$H$13 -> 0.082191781 | I25: =I11/$I$13 -> 0.082191781 | J25: =J11/$J$13 -> 0.082191781 | K25: =K11/$K$13 -> 0.082191781 | L25: =AVERAGE(B25:K25) -> 0.082191781
A26: Skill Gap ,Retaining resources and workforce Management | B26: =B12/$B$13 -> 0.10958904 | C26: =C12/$C$13 -> 0.10958904 | D26: =D12/$D$13 -> 0.10958904 | E26: =E12/$E$13 -> 0.10958904 | F26: =F12/$F$13 -> 0.10958904 | G26: =G12/$G$13 -> 0.10958904 | H26: =H12/$H$13 -> 0.10958904 | I26: =I12/$I$13 -> 0.10958904 | J26: =J12/$J$13 -> 0.10958904 | K26: =K12/$K$13 -> 0.10958904 | L26: =AVERAGE(B26:K26) -> 0.10958904
A27: SUM | B27: =SUM(B17:B26) -> 1 | C27: =SUM(C17:C26) -> 1 | D27: =SUM(D17:D26) -> 1 | E27: =SUM(E17:E26) -> 1 | F27: =SUM(F17:F26) -> 1 | G27: =SUM(G17:G26) -> 1 | H27: =SUM(H17:H26) -> 1 | I27: =SUM(I17:I26) -> 1 | ... L27: =SUM(L17:L26) -> 1

Sheet AHP
A1: Relative Importance of Dimensions Matrix
B2: Buy process, Demand Planning & Procurement | C2: Current Operational Process, Legacy & new machine to balance | D2: Effortable Digital technologies | E2: Owner's viewpoints | F2: Growth and Effeciency.Challenges to penetrate the global market. | G2: Certification & Standarization | H2: Financial challenges, lack of transparency in institutional support and knowledge gap on Ecosystem Integration | I2: Administrative, Operational challenges & Eco system Integration challenges | J2: Engaging local hire | K2: Skill Gap, Retaining resources and workforce Management | L2: Product | M2: Geometric Mean (GM) | N2: Normalised Values (A2) | O2: A3 = A1xA2 | P2: A4 = A3/A2
A3: Buy process,Demand Planning & Procurement | B3: ='Importance Mapping'!D2/'Importance Mapping'!$D$2 -> 1 | C3: ='Importance Mapping'!D2/'Importance Mapping'!$D$3 -> 1 | D3: ='Importance Mapping'!D2/'Importance Mapping'!$D$4 -> 0.6 | E3: ='Importance Mapping'!D2/'Importance Mapping'!$D$5 -> 0.75 | F3: ='Importance Mapping'!D2/'Importance Mapping'!$D$6 -> 0.66666667 | G3: ='Importance Mapping'!D2/'Importance Mapping'!$D$7 -> 0.6 | H3: ='Importance Mapping'!D2/'Importance Mapping'!$D$8 -> 1 | I3: ='Importance Mapping'!D2/'Importance Mapping'!$D$9 -> 1.5 | J3: ='Importance Mapping'!D2/'Importance Mapping'!$D$10 -> 1 | K3: ='Importance Mapping'!D2/'Importance Mapping'!$D$11 -> 0.75 | L3: =PRODUCT(B3:K3) -> 0.2025 | M3: =POWER(L3,0.1) -> 0.85239816 | N3: =M3/$M$13 -> 0.082191781 | O3: =(B3*N3+C3*N4+D3*N5+E3*N6+F3*N7+G3*N8+H3*N9+I3*N10+J3*N11+K3*N12) -> 0.82191781 | P3: =O3/N3 -> 10
A4: Current Operational Process, Legacy & new machine to balance | B4: ='Importance Mapping'!D3/'Importance Mapping'!$D$2 -> 1 | C4: ='Importance Mapping'!D3/'Importance Mapping'!$D$3 -> 1 | D4: ='Importance Mapping'!D3/'Importance Mapping'!$D$4 -> 0.6 | E4: ='Importance Mapping'!D3/'Importance Mapping'!$D$5 -> 0.75 | F4: ='Importance Mapping'!D3/'Importance Mapping'!$D$6 -> 0.66666667 | G4: ='Importance Mapping'!D3/'Importance Mapping'!$D$7 -> 0.6 | H4: ='Importance Mapping'!D3/'Importance Mapping'!$D$8 -> 1 | I4: ='Importance Mapping'!D3/'Importance Mapping'!$D$9 -> 1.5 | J4: ='Importance Mapping'!D3/'Importance Mapping'!$D$10 -> 1 | K4: ='Importance Mapping'!D3/'Importance Mapping'!$D$11 -> 0.75 | L4: =PRODUCT(B4:K4) -> 0.2025 | M4: =POWER(L4,0.1) -> 0.85239816 | N4: =M4/$M$13 -> 0.082191781 | O4: =B4*N3+C4*N4+D4*N5+E4*N6+F4*N7+G4*N8+H4*N9+I4*N10+J4*N11+K4*N12 -> 0.82191781 | P4: =O4/N4 -> 10
A5: Effortable Digital technologies | B5: ='Importance Mapping'!D4/'Importance Mapping'!$D$2 -> 1.6666667 | C5: ='Importance Mapping'!D4/'Importance Mapping'!$D$3 -> 1.6666667 | D5: ='Importance Mapping'!D4/'Importance Mapping'!$D$4 -> 1 | E5: ='Importance Mapping'!D4/'Importance Mapping'!$D$5 -> 1.25 | F5: ='Importance Mapping'!D4/'Importance Mapping'!$D$6 -> 1.1111111 | G5: ='Importance Mapping'!D4/'Importance Mapping'!$D$7 -> 1 | H5: ='Importance Mapping'!D4/'Importance Mapping'!$D$8 -> 1.6666667 | I5: ='Importance Mapping'!D4/'Importance Mapping'!$D$9 -> 2.5 | J5: ='Importance Mapping'!D4/'Importance Mapping'!$D$10 -> 1.6666667 | K5: ='Importance Mapping'!D4/'Importance Mapping'!$D$11 -> 1.25 | L5: =PRODUCT(B5:K5) -> 33.489798 | M5: =POWER(L5,0.1) -> 1.4206636 | N5: =M5/$M$13 -> 0.1369863 | O5: =B5*N3+C5*N4+D5*N5+E5*N6+F5*N7+G5*N8+H5*N9+I5*N10+J5*N11+K5*N12 -> 1.369863 | P5: =O5/N5 -> 10
A6: Owner's viewpoints | B6: ='Importance Mapping'!D5/'Importance Mapping'!$D$2 -> 1.3333333 | C6: ='Importance Mapping'!D5/'Importance Mapping'!$D$3 -> 1.3333333 | D6: ='Importance Mapping'!D5/'Importance Mapping'!$D$4 -> 0.8 | E6: ='Importance Mapping'!D5/'Importance Mapping'!$D$5 -> 1 | F6: ='Importance Mapping'!D5/'Importance Mapping'!$D$6 -> 0.88888889 | G6: ='Importance Mapping'!D5/'Importance Mapping'!$D$7 -> 0.8 | H6: ='Importance Mapping'!D5/'Importance Mapping'!$D$8 -> 1.3333333 | I6: ='Importance Mapping'!D5/'Importance Mapping'!$D$9 -> 2 | J6: ='Importance Mapping'!D5/'Importance Mapping'!$D$10 -> 1.3333333 | K6: ='Importance Mapping'!D5/'Importance Mapping'!$D$11 -> 1 | L6: =PRODUCT(B6:K6) -> 3.5959396 | M6: =POWER(L6,0.1) -> 1.1365309 | N6: =M6/$M$13 -> 0.10958904 | O6: =B6*N3+C6*N4+D6*N5+E6*N6+F6*N7+G6*N8+H6*N9+I6*N10+J6*N11+K6*N12 -> 1.0958904 | P6: =O6/N6 -> 10
A7: Growth and Effeciency. Challenges to penetrate the global market. | B7: ='Importance Mapping'!D6/'Importance Mapping'!$D$2 -> 1.5 | C7: ='Importance Mapping'!D6/'Importance Mapping'!$D$3 -> 1.5 | D7: ='Importance Mapping'!D6/'Importance Mapping'!$D$4 -> 0.9 | E7: ='Importance Mapping'!D6/'Importance Mapping'!$D$5 -> 1.125 | F7: ='Importance Mapping'!D6/'Importance Mapping'!$D$6 -> 1 | G7: ='Importance Mapping'!D6/'Importance Mapping'!$D$7 -> 0.9 | H7: ='Importance Mapping'!D6/'Importance Mapping'!$D$8 -> 1.5 | I7: ='Importance Mapping'!D6/'Importance Mapping'!$D$9 -> 2.25 | J7: ='Importance Mapping'!D6/'Importance Mapping'!$D$10 -> 1.5 | K7: ='Importance Mapping'!D6/'Importance Mapping'!$D$11 -> 1.125 | L7: =PRODUCT(B7:K7) -> 11.67717 | M7: =POWER(L7,0.1) -> 1.2785972 | N7: =M7/$M$13 -> 0.12328767 | O7: =B7*N3+C7*N4+D7*N5+E7*N6+F7*N7+G7*N8+H7*N9+I7*N10+J7*N11+K7*N12 -> 1.2328767 | P7: =O7/N7 -> 10
A8: Certification &Standarization | B8: ='Importance Mapping'!D7/'Importance Mapping'!$D$2 -> 1.6666667 | C8: ='Importance Mapping'!D7/'Importance Mapping'!$D$3 -> 1.6666667 | D8: ='Importance Mapping'!D7/'Importance Mapping'!$D$4 -> 1 | E8: ='Importance Mapping'!D7/'Importance Mapping'!$D$5 -> 1.25 | F8: ='Importance Mapping'!D7/'Importance Mapping'!$D$6 -> 1.1111111 | G8: ='Importance Mapping'!D7/'Importance Mapping'!$D$7 -> 1 | H8: ='Importance Mapping'!D7/'Importance Mapping'!$D$8 -> 1.6666667 | I8: ='Importance Mapping'!D7/'Importance Mapping'!$D$9 -> 2.5 | J8: ='Importance Mapping'!D7/'Importance Mapping'!$D$10 -> 1.6666667 | K8: ='Importance Mapping'!D7/'Importance Mapping'!$D$11 -> 1.25 | L8: =PRODUCT(B8:K8) -> 33.489798 | M8: =POWER(L8,0.1) -> 1.4206636 | N8: =M8/$M$13 -> 0.1369863 | O8: =B8*N3+C8*N4+D8*N5+E8*N6+F8*N7+G8*N8+H8*N9+I8*N10+J8*N11+K8*N12 -> 1.369863 | P8: =O8/N8 -> 10
A9: Financial challenges, lack of transparency in institutional support and knowledge gap on Ecosystem Integration | B9: ='Importance Mapping'!D8/'Importance Mapping'!$D$2 -> 1 | C9: ='Importance Mapping'!D8/'Importance Mapping'!$D$3 -> 1 | D9: ='Importance Mapping'!D8/'Importance Mapping'!$D$4 -> 0.6 | E9: ='Importance Mapping'!D8/'Importance Mapping'!$D$5 -> 0.75 | F9: ='Importance Mapping'!D8/'Importance Mapping'!$D$6 -> 0.66666667 | G9: ='Importance Mapping'!D8/'Importance Mapping'!$D$7 -> 0.6 | H9: ='Importance Mapping'!D8/'Importance Mapping'!$D$8 -> 1 | I9: ='Importance Mapping'!D8/'Importance Mapping'!$D$9 -> 1.5 | J9: ='Importance Mapping'!D8/'Importance Mapping'!$D$10 -> 1 | K9: ='Importance Mapping'!D8/'Importance Mapping'!$D$11 -> 0.75 | L9: =PRODUCT(B9:K9) -> 0.2025 | M9: =POWER(L9,0.1) -> 0.85239816 | N9: =M9/$M$13 -> 0.082191781 | O9: =B9*N3+C9*N4+D9*N5+E9*N6+F9*N7+G9*N8+H9*N9+I9*N10+J9*N11+K9*N12 -> 0.82191781 | P9: =O9/N9 -> 10
A10: Administrative, Operational challenges & Eco system Integration challenges | B10: ='Importance Mapping'!D9/'Importance Mapping'!$D$2 -> 0.66666667 | C10: ='Importance Mapping'!D9/'Importance Mapping'!$D$3 -> 0.66666667 | D10: ='Importance Mapping'!D9/'Importance Mapping'!$D$4 -> 0.4 | E10: ='Importance Mapping'!D9/'Importance Mapping'!$D$5 -> 0.5 | F10: ='Importance Mapping'!D9/'Importance Mapping'!$D$6 -> 0.44444444 | G10: ='Importance Mapping'!D9/'Importance Mapping'!$D$7 -> 0.4 | H10: ='Importance Mapping'!D9/'Importance Mapping'!$D$8 -> 0.66666667 | I10: ='Importance Mapping'!D9/'Importance Mapping'!$D$9 -> 1 | J10: ='Importance Mapping'!D9/'Importance Mapping'!$D$10 -> 0.66666667 | K10: ='Importance Mapping'!D9/'Importance Mapping'!$D$11 -> 0.5 | L10: =PRODUCT(B10:K10) -> 0.0035116598 | M10: =POWER(L10,0.1) -> 0.56826544 | N10: =M10/$M$13 -> 0.054794521 | O10: =B10*N3+C10*N4+D10*N5+E10*N6+F10*N7+G10*N8+H10*N9+I10*N10+J10*N11+K10*N12 -> 0.54794521 | P10: =O10/N10 -> 10
A11: Engaging local hire | B11: ='Importance Mapping'!D10/'Importance Mapping'!$D$2 -> 1 | C11: ='Importance Mapping'!D10/'Importance Mapping'!$D$3 -> 1 | D11: ='Importance Mapping'!D10/'Importance Mapping'!$D$4 -> 0.6 | E11: ='Importance Mapping'!D10/'Importance Mapping'!$D$5 -> 0.75 | F11: ='Importance Mapping'!D10/'Importance Mapping'!$D$6 -> 0.66666667 | G11: ='Importance Mapping'!D10/'Importance Mapping'!$D$7 -> 0.6 | H11: ='Importance Mapping'!D10/'Importance Mapping'!$D$8 -> 1 | I11: ='Importance Mapping'!D10/'Importance Mapping'!$D$9 -> 1.5 | J11: ='Importance Mapping'!D10/'Importance Mapping'!$D$10 -> 1 | K11: ='Importance Mapping'!D10/'Importance Mapping'!$D$11 -> 0.75 | L11: =PRODUCT(B11:K11) -> 0.2025 | M11: =POWER(L11,0.1) -> 0.85239816 | N11: =M11/$M$13 -> 0.082191781 | O11: =B11*N3+C11*N4+D11*N5+E11*N6+F11*N7+G11*N8+H11*N9+I11*N10+J11*N11+K11*N12 -> 0.82191781 | P11: =O11/N11 -> 10
A12: Skill Gap, Retaining resources and workforce Management | B12: ='Importance Mapping'!D11/'Importance Mapping'!$D$2 -> 1.3333333 | C12: ='Importance Mapping'!D11/'Importance Mapping'!$D$3 -> 1.3333333 | D12: ='Importance Mapping'!D11/'Importance Mapping'!$D$4 -> 0.8 | E12: ='Importance Mapping'!D11/'Importance Mapping'!$D$5 -> 1 | F12: ='Importance Mapping'!D11/'Importance Mapping'!$D$6 -> 0.88888889 | G12: ='Importance Mapping'!D11/'Importance Mapping'!$D$7 -> 0.8 | H12: ='Importance Mapping'!D11/'Importance Mapping'!$D$8 -> 1.3333333 | I12: ='Importance Mapping'!D11/'Importance Mapping'!$D$9 -> 2 | J12: ='Importance Mapping'!D11/'Importance Mapping'!$D$10 -> 1.3333333 | K12: ='Importance Mapping'!D11/'Importance Mapping'!$D$11 -> 1 | L12: =PRODUCT(B12:K12) -> 3.5959396 | M12: =POWER(L12,0.1) -> 1.1365309 | N12: =M12/$M$13 -> 0.10958904 | O12: =B12*N3+C12*N4+D12*N5+E12*N6+F12*N7+G12*N8+H12*N9+I12*N10+J12*N11+K12*N12 -> 1.0958904 | P12: =O12/N12 -> 10
M13: =SUM(M3:M12) -> 10.370844 | N13: =SUM(N3:N12) -> 1 | O13: λmax = | P13: =SUM(P3:P12)/10 -> 10
A15: WEIGHTS (A2) | B15: 0.082191781 | C15: 0.082191781 | D15: 0.1369863 | E15: 0.10958904 | F15: 0.12328767 | G15: 0.1369863 | H15: 0.082191781 | I15: 0.054794521 | J15: 0.082191781 | K15: 0.10958904 | L15: =SUM(B15:K15) -> 1 | O15: CI = (λmax-N) / (N-1) | P15: =(P13-10)/9 -> 0
O16: RI = | P16: 1.49
A17: These weigths can be applied later on to find out the best suitable alternative. | F17: Whatever values of relative index we have taken is said to be consistent if value of CR is less than 0.1 | O17: CR = CI / RI | P17: =P15/P16 -> 0
F18: Therefore, the values we have taken is consistent. | M18: CI = Consistency Index
M19: RI = Random Index
M20: CR = Consistency Ratio
